
import { render, screen } from '@testing-library/react';
import { describe, it, expect, vi } from 'vitest';
import ErrorBoundary from './ErrorBoundary';

// Component that throws an error
const ThrowError = ({ shouldThrow }: { shouldThrow: boolean }) => {
  if (shouldThrow) {
    throw new Error('Test error');
  }
  return <div>No error</div>;
};

describe('ErrorBoundary', () => {
  // Suppress console errors during tests
  const originalConsoleError = console.error;
  beforeEach(() => {
    console.error = vi.fn();
  });
  
  afterEach(() => {
    console.error = originalConsoleError;
  });

  it('renders children when there is no error', () => {
    render(
      <ErrorBoundary>
        <div>Test child</div>
      </ErrorBoundary>
    );
    
    expect(screen.getByText('Test child')).toBeInTheDocument();
  });

  it('renders error UI when a child throws', () => {
    // Mock console.error to prevent test output noise
    vi.spyOn(console, 'error').mockImplementation(() => {});
    
    render(
      <ErrorBoundary>
        <ThrowError shouldThrow={true} />
      </ErrorBoundary>
    );
    
    expect(screen.getByText('Something went wrong')).toBeInTheDocument();
    expect(screen.getByText('Test error')).toBeInTheDocument();
    expect(screen.getByText('Try again')).toBeInTheDocument();
  });

  it('renders custom fallback when provided', () => {
    render(
      <ErrorBoundary fallback={<div>Custom fallback</div>}>
        <ThrowError shouldThrow={true} />
      </ErrorBoundary>
    );
    
    expect(screen.getByText('Custom fallback')).toBeInTheDocument();
  });
});
